Workbook
Name Analysis: 'Analysis Table'!$C$2:$C$498
Name EventRates: 'Moody''s Reference Data'!$C$2:$C$500
Name ModelProfiles: 'Moody''s Reference Data'!$A$2:$A$500
Name OutputProfiles: 'Moody''s Reference Data'!$B$2:$B$500
Name Portfolio: Portfolios!$A$2:$A$500
Name Treaty: 'Reinsurance Treaties'!$A$2:$A$498

Sheet Metadata
A1: Current Date Value
A2: EDM Data Version | B2: 23.0.0
A3: Geocode Version | B3: 23.0.0
A4: Hazard Version | B4: 23.0.0
A5: DLM Model Version | B5: 23
A6: Validate DLM Model Versions? | B6: Y
A7: Wildfire HD Model Version | B7: 2
A8: SCS HD Model Version | B8: 1
A9: Inland Flood HD Model Version | B9: 1.2
A10: Validate HD Model Versions? | B10: Y
A11: Export RDM Name | B11: =_xlfn.CONCAT("RMS_RDM_", B1, "_QEM_USAP") -> RMS_RDM__QEM_USAP

Sheet Validations
A1: Case | B1: Count of Failures
A2: If Peril = 'ST' and Analysis Profile contains 'Low Frq' -> Analysis Name must end with 'Low_Frq' | B2: {=SUMPRODUCT((RIGHT('Analysis Table'!$A$2:$A$498,2)="ST")*(ISNUMBER(SEARCH("Low Frq",'Analysis Table'!$D$2:$D$498)))*(RIGHT('Analysis Table'!$C$2:$C$498,7)<>"Low_Frq"))} -> 0
A3: If Peril = 'ST' and Analysis Profile contains 'High Frq' -> Analysis Name must end with 'High_Frq' | B3: {=SUMPRODUCT((RIGHT('Analysis Table'!$A$2:$A$498,2)="ST")*(ISNUMBER(SEARCH("High Frq",'Analysis Table'!$D$2:$D$498)))*(RIGHT('Analysis Table'!$C$2:$C$498,8)<>"High_Frq"))} -> 0
A4: If Analysis Profile contains 'HU' and Event Rate contains 'Historical' -> Analysis Name must end with 'LT' | B4: {=SUMPRODUCT((ISNUMBER(SEARCH("HU",'Analysis Table'!$D$2:$D$498)))*(ISNUMBER(SEARCH("Historical",'Analysis Table'!$F$2:$F$498)))*(RIGHT('Analysis Table'!$C$2:$C$498,2)<>"LT"))} -> 0
A5: If Analysis Profiles contains 'HU' and Event Rate contains 'Stochastic' -> Analysis Name must end with 'NT' | B5: {=SUMPRODUCT((ISNUMBER(SEARCH("HU",'Analysis Table'!$D$2:$D$498)))*(ISNUMBER(SEARCH("Stochastic",'Analysis Table'!$F$2:$F$498)))*(RIGHT('Analysis Table'!$C$2:$C$498,2)<>"NT"))} -> 0
A6: If Analysis Profile contains 'FL' and Event Rate contains 'Historical' -> Analysis Name must end with 'LT' | B6: {=SUMPRODUCT((ISNUMBER(SEARCH("FL",'Analysis Table'!$D$2:$D$498)))*(ISNUMBER(SEARCH("Historical",'Analysis Table'!$F$2:$F$498)))*(RIGHT('Analysis Table'!$C$2:$C$498,2)<>"LT"))} -> 0
A7: If Analysis Profile contains 'FL' and Event Rate contains 'Stochastic' -> Analysis Name must end with 'NT' | B7: {=SUMPRODUCT((ISNUMBER(SEARCH("FL",'Analysis Table'!$D$2:$D$498)))*(ISNUMBER(SEARCH("Stochastic",'Analysis Table'!$F$2:$F$498)))*(RIGHT('Analysis Table'!$C$2:$C$498,2)<>"NT"))} -> 0
A8: If Group Name contains '_LT_' -> Group Members cannot contain 'NT' | B8: {=SUMPRODUCT((ISNUMBER(SEARCH("_LT_",Groupings!$A2:$A499)))*((MMULT(--(ISNUMBER(SEARCH("_NT",Groupings!$B2:$AY499))),TRANSPOSE(COLUMN(Groupings!$B:$AY)^0))>0)))} -> 0
A9: If Group Name contains '_NT_' -> Group Members cannot contain 'LT' | B9: {=SUMPRODUCT((ISNUMBER(SEARCH("_NT_",Groupings!$A2:$A499)))*((MMULT(--(ISNUMBER(SEARCH("_LT",Groupings!$B2:$AY499))),TRANSPOSE(COLUMN(Groupings!$B:$AY)^0))>0)))} -> 0

Sheet Databases
A1: Database | B1: Store in Data Bridge?
A2: =_xlfn.CONCAT("RMS_EDM_",Metadata!$B$1,"_Quarterly_CBAP") -> RMS_EDM__Quarterly_CBAP | B2: Y
A3: =_xlfn.CONCAT("RMS_EDM_",Metadata!$B$1,"_Quarterly_USEQ") -> RMS_EDM__Quarterly_USEQ | B3: Y
A4: =_xlfn.CONCAT("RMS_EDM_",Metadata!$B$1,"_Quarterly_USFF") -> RMS_EDM__Quarterly_USFF | B4: Y
A5: =_xlfn.CONCAT("RMS_EDM_",Metadata!$B$1,"_Quarterly_USFL") -> RMS_EDM__Quarterly_USFL | B5: Y
A6: =_xlfn.CONCAT("RMS_EDM_",Metadata!$B$1,"_Quarterly_USHU") -> RMS_EDM__Quarterly_USHU | B6: Y
A7: =_xlfn.CONCAT("RMS_EDM_",Metadata!$B$1,"_Quarterly_USST") -> RMS_EDM__Quarterly_USST | B7: Y
A8: =_xlfn.CONCAT("RMS_EDM_",Metadata!$B$1,"_Quarterly_USWF") -> RMS_EDM__Quarterly_USWF | B8: Y

Sheet Portfolios
A1: Portfolio | B1: Database | C1: Import File | D1: Base Portfolio?
A2: CBHU | B2: =_xlfn.CONCAT("RMS_EDM_",Metadata!$B$1,"_Quarterly_CBAP") -> RMS_EDM__Quarterly_CBAP | C2: CBHU | D2: Y
A3: CBEQ | B3: =_xlfn.CONCAT("RMS_EDM_",Metadata!$B$1,"_Quarterly_CBAP") -> RMS_EDM__Quarterly_CBAP | C3: CBEQ | D3: Y
A4: USEQ_Clay_Homes | B4: =_xlfn.CONCAT("RMS_EDM_",Metadata!$B$1,"_Quarterly_USEQ") -> RMS_EDM__Quarterly_USEQ | C4: USEQ | D4: N
A5: USEQ_Clay_21st | B5: =_xlfn.CONCAT("RMS_EDM_",Metadata!$B$1,"_Quarterly_USEQ") -> RMS_EDM__Quarterly_USEQ | C5: USEQ | D5: N
A6: USEQ_CHFS | B6: =_xlfn.CONCAT("RMS_EDM_",Metadata!$B$1,"_Quarterly_USEQ") -> RMS_EDM__Quarterly_USEQ | C6: USEQ | D6: N
A7: USEQ_Condo | B7: =_xlfn.CONCAT("RMS_EDM_",Metadata!$B$1,"_Quarterly_USEQ") -> RMS_EDM__Quarterly_USEQ | C7: USEQ | D7: N
A8: USEQ_Renters | B8: =_xlfn.CONCAT("RMS_EDM_",Metadata!$B$1,"_Quarterly_USEQ") -> RMS_EDM__Quarterly_USEQ | C8: USEQ | D8: N
A9: USEQ_Manufactured | B9: =_xlfn.CONCAT("RMS_EDM_",Metadata!$B$1,"_Quarterly_USEQ") -> RMS_EDM__Quarterly_USEQ | C9: USEQ | D9: N
A10: USEQ | B10: =_xlfn.CONCAT("RMS_EDM_",Metadata!$B$1,"_Quarterly_USEQ") -> RMS_EDM__Quarterly_USEQ | C10: USEQ | D10: Y
A11: USFF_Geico_75HIP2 | B11: =_xlfn.CONCAT("RMS_EDM_",Metadata!$B$1,"_Quarterly_USFF") -> RMS_EDM__Quarterly_USFF | C11: USFF | D11: N
A12: USFF_Geico_HIP1 | B12: =_xlfn.CONCAT("RMS_EDM_",Metadata!$B$1,"_Quarterly_USFF") -> RMS_EDM__Quarterly_USFF | C12: USFF | D12: N
A13: USFF_Clay_Homes | B13: =_xlfn.CONCAT("RMS_EDM_",Metadata!$B$1,"_Quarterly_USFF") -> RMS_EDM__Quarterly_USFF | C13: USFF | D13: N
A14: USFF_Clay_21st | B14: =_xlfn.CONCAT("RMS_EDM_",Metadata!$B$1,"_Quarterly_USFF") -> RMS_EDM__Quarterly_USFF | C14: USFF | D14: N
A15: USFF_Other | B15: =_xlfn.CONCAT("RMS_EDM_",Metadata!$B$1,"_Quarterly_USFF") -> RMS_EDM__Quarterly_USFF | C15: USFF | D15: N
A16: USFF_CHFS | B16: =_xlfn.CONCAT("RMS_EDM_",Metadata!$B$1,"_Quarterly_USFF") -> RMS_EDM__Quarterly_USFF | C16: USFF | D16: N
A17: USFF_Condo | B17: =_xlfn.CONCAT("RMS_EDM_",Metadata!$B$1,"_Quarterly_USFF") -> RMS_EDM__Quarterly_USFF | C17: USFF | D17: N
A18: USFF_Renters | B18: =_xlfn.CONCAT("RMS_EDM_",Metadata!$B$1,"_Quarterly_USFF") -> RMS_EDM__Quarterly_USFF | C18: USFF | D18: N
A19: USFF_Manufactured | B19: =_xlfn.CONCAT("RMS_EDM_",Metadata!$B$1,"_Quarterly_USFF") -> RMS_EDM__Quarterly_USFF | C19: USFF | D19: N
A20: USFF_Lender_P | B20: =_xlfn.CONCAT("RMS_EDM_",Metadata!$B$1,"_Quarterly_USFF") -> RMS_EDM__Quarterly_USFF | C20: USFF | D20: N
A21: USFF | B21: =_xlfn.CONCAT("RMS_EDM_",Metadata!$B$1,"_Quarterly_USFF") -> RMS_EDM__Quarterly_USFF | C21: USFF | D21: Y
A22: USFL_Other_Clay_Home | B22: =_xlfn.CONCAT("RMS_EDM_",Metadata!$B$1,"_Quarterly_USFL") -> RMS_EDM__Quarterly_USFL | C22: USFL_Other | D22: N
A23: USFL_Other_Clay_21st | B23: =_xlfn.CONCAT("RMS_EDM_",Metadata!$B$1,"_Quarterly_USFL") -> RMS_EDM__Quarterly_USFL | C23: USFL_Other | D23: N
A24: USFL_Other_Other | B24: =_xlfn.CONCAT("RMS_EDM_",Metadata!$B$1,"_Quarterly_USFL") -> RMS_EDM__Quarterly_USFL | C24: USFL_Other | D24: N
A25: USFL_Other_Renters | B25: =_xlfn.CONCAT("RMS_EDM_",Metadata!$B$1,"_Quarterly_USFL") -> RMS_EDM__Quarterly_USFL | C25: USFL_Other | D25: N
A26: USFL_Other_Maufactu | B26: =_xlfn.CONCAT("RMS_EDM_",Metadata!$B$1,"_Quarterly_USFL") -> RMS_EDM__Quarterly_USFL | C26: USFL_Other | D26: N
A27: USFL_Other_CB | B27: =_xlfn.CONCAT("RMS_EDM_",Metadata!$B$1,"_Quarterly_USFL") -> RMS_EDM__Quarterly_USFL | C27: USFL_Other | D27: N
A28: USFL_Other_Lender_P | B28: =_xlfn.CONCAT("RMS_EDM_",Metadata!$B$1,"_Quarterly_USFL") -> RMS_EDM__Quarterly_USFL | C28: USFL_Other | D28: N
A29: USFL_Other | B29: =_xlfn.CONCAT("RMS_EDM_",Metadata!$B$1,"_Quarterly_USFL") -> RMS_EDM__Quarterly_USFL | C29: USFL_Other | D29: Y
A30: USFL_Excess | B30: =_xlfn.CONCAT("RMS_EDM_",Metadata!$B$1,"_Quarterly_USFL") -> RMS_EDM__Quarterly_USFL | C30: USFL_Excess | D30: Y
A31: USFL_Commercial | B31: =_xlfn.CONCAT("RMS_EDM_",Metadata!$B$1,"_Quarterly_USFL") -> RMS_EDM__Quarterly_USFL | C31: USFL_Commercial | D31: Y
A32: USHU_Leak_Geico_75H2 | B32: =_xlfn.CONCAT("RMS_EDM_",Metadata!$B$1,"_Quarterly_USHU") -> RMS_EDM__Quarterly_USHU | C32: USHU_Leak | D32: N
A33: USHU_Leak_Geico_HIP1 | B33: =_xlfn.CONCAT("RMS_EDM_",Metadata!$B$1,"_Quarterly_USHU") -> RMS_EDM__Quarterly_USHU | C33: USHU_Leak | D33: N
A34: USHU_Full_Clay_Homes | B34: =_xlfn.CONCAT("RMS_EDM_",Metadata!$B$1,"_Quarterly_USHU") -> RMS_EDM__Quarterly_USHU | C34: USHU_Full | D34: N
A35: USHU_Full_Clay_21st | B35: =_xlfn.CONCAT("RMS_EDM_",Metadata!$B$1,"_Quarterly_USHU") -> RMS_EDM__Quarterly_USHU | C35: USHU_Full | D35: N
A36: USHU_Full_Other | B36: =_xlfn.CONCAT("RMS_EDM_",Metadata!$B$1,"_Quarterly_USHU") -> RMS_EDM__Quarterly_USHU | C36: USHU_Full | D36: N
A37: USHU_Full_Renters | B37: =_xlfn.CONCAT("RMS_EDM_",Metadata!$B$1,"_Quarterly_USHU") -> RMS_EDM__Quarterly_USHU | C37: USHU_Full | D37: N
A38: USHU_Full_Manufact | B38: =_xlfn.CONCAT("RMS_EDM_",Metadata!$B$1,"_Quarterly_USHU") -> RMS_EDM__Quarterly_USHU | C38: USHU_Full | D38: N
A39: USHU_Full_Lender_P | B39: =_xlfn.CONCAT("RMS_EDM_",Metadata!$B$1,"_Quarterly_USHU") -> RMS_EDM__Quarterly_USHU | C39: USHU_Full | D39: N
A40: USHU_Leak_Clay_Homes | B40: =_xlfn.CONCAT("RMS_EDM_",Metadata!$B$1,"_Quarterly_USHU") -> RMS_EDM__Quarterly_USHU | C40: USHU_Leak | D40: N
...

Sheet Reinsurance Treaties
A1: Treaty Name | B1: Treaty Number | C1: Type | D1: Per-Risk Limit | E1: Occurrence Limit | F1: Attachment Point | G1: Inception Date | H1: Expiration Date | I1: Currency | J1: Attachment Basis | K1: Exposure Level | L1: % Covered | M1: % Place | N1: % Share | O1: % Retention | P1: Premium | Q1: Reinstatements | R1: % Reinstatement Charge | S1: Aggregate Limit | T1: Aggregate Deductible Amount | U1: Inuring Priority | V1: Producer | W1: Tags
A2: XPR_1_95 | B2: XPR_1_95 | C2: Working Excess | D2: 3000000 | E2: 9000000 | F2: 2000000 | G2: 36526 | H2: 47848 | I2: US Dollar | J2: Losses Occurring | K2: Location | L2: 100 | M2: 95 | N2: 100 | O2: 100 | P2: 0 | Q2: 99 | R2: 0 | S2: 0 | T2: 0 | U2: 1
A3: XPR_1_100 | B3: XPR_1_100 | C3: Working Excess | D3: 5000000 | E3: 10000000 | F3: 5000000 | G3: 36526 | H3: 47848 | I3: US Dollar | J3: Losses Occurring | K3: Location | L3: 100 | M3: 100 | N3: 100 | O3: 100 | P3: 0 | Q3: 99 | R3: 0 | S3: 0 | T3: 0 | U3: 1
A4: Geico_2.075QS | B4: Geico_2.075QS | C4: Quota Share | D4: 3000000 | E4: 169835616 | F4: 0 | G4: 36526 | H4: 47848 | I4: US Dollar | J4: Losses Occurring | K4: Location | L4: 100 | M4: 75 | N4: 100 | O4: 100 | P4: 0 | Q4: 99 | R4: 0 | S4: 0 | T4: 0 | U4: 1

Sheet GeoHaz Thresholds
A1: Geocode Level | B1: Import File | C1: % of Grand Total | D1: Threshold %
A2: Null | B2: CBEQ | C2: 0 | D2: 1
A3: Coordinate | B3: CBEQ | C3: 20 | D3: 30
A4: Street address | B4: CBEQ | C4: 0 | D4: 30
A5: High Resolution Postcode / Street Block | B5: CBEQ | C5: 0 | D5: 1
A6: Street Name | B6: CBEQ | C6: 0 | D6: 30
A7: Postcode | B7: CBEQ | C7: 80 | D7: 30
A8: City District/ Admin4 | B8: CBEQ | C8: 0 | D8: 1
A9: City/Town | B9: CBEQ | C9: 0 | D9: 1
A10: District / Municipality/Admin3 | B10: CBEQ | C10: 0 | D10: 1
A11: State/Province/ Admin1 | B11: CBEQ | C11: 0 | D11: 1
A12: County/Admin2 | B12: CBEQ | C12: 0 | D12: 1
A13: Null | B13: CBHU | C13: 0 | D13: 0.1
... A122: County/Admin2 | B122: USFL_Other | C122: 0 | D122: 0.001

Sheet Analysis Table
A1: Database | B1: Portfolio | C1: Analysis Name | D1: Analysis Profile | E1: Output Profile | F1: Event Rate | G1: Reinsurance Treaty 1 | H1: Reinsurance Treaty 2 | I1: Reinsurance Treaty 3 | J1: Reinsurance Treaty 4 | K1: Reinsurance Treaty 5 | L1: Tag 1 | M1: Tag 2 | N1: Tag 3 | O1: Tag 4 | P1: Tag 5
A2: =_xlfn.CONCAT("RMS_EDM_",Metadata!$B$1,"_Quarterly_CBAP") -> RMS_EDM__Quarterly_CBAP | B2: CBHU | C2: CBHU_LT | D2: DLM CBHU v23 | E2: Modeling_Output_Profile | F2: RMS 2023 Historical Event Rates | G2: XPR_1_95 | H2: XPR_1_100 | L2: =_xlfn.CONCAT(Metadata!$B$1,"_Quarterly_CBHU_LT") -> _Quarterly_CBHU_LT
A3: =_xlfn.CONCAT("RMS_EDM_",Metadata!$B$1,"_Quarterly_CBAP") -> RMS_EDM__Quarterly_CBAP | B3: CBHU | C3: CBHU_NT | D3: DLM CBHU v23 | E3: Modeling_Output_Profile | F3: RMS 2023 Stochastic Event Rates | G3: XPR_1_95 | H3: XPR_1_100 | L3: =_xlfn.CONCAT(Metadata!$B$1,"_Quarterly_CBHU_NT") -> _Quarterly_CBHU_NT
A4: =_xlfn.CONCAT("RMS_EDM_",Metadata!$B$1,"_Quarterly_CBAP") -> RMS_EDM__Quarterly_CBAP | B4: CBEQ | C4: CBEQ | D4: DLM CBEQ v23 | E4: Modeling_Output_Profile | F4: RMS Stochastic Event Rates | G4: XPR_1_95 | H4: XPR_1_100 | L4: =_xlfn.CONCAT(Metadata!$B$1,"_Quarterly_CBEQ") -> _Quarterly_CBEQ
A5: =_xlfn.CONCAT("RMS_EDM_",Metadata!$B$1,"_Quarterly_USEQ") -> RMS_EDM__Quarterly_USEQ | B5: USEQ_Clay_Homes | C5: USEQ_Clay_Homes | D5: DLM USEQ v23 | E5: Modeling_Output_Profile | F5: RMS 17.0 NA Stochastic Event Rates | L5: =_xlfn.CONCAT(Metadata!$B$1,"_Quarterly_USEQ") -> _Quarterly_USEQ
A6: =_xlfn.CONCAT("RMS_EDM_",Metadata!$B$1,"_Quarterly_USEQ") -> RMS_EDM__Quarterly_USEQ | B6: USEQ_Clay_21st | C6: USEQ_Clay_21st | D6: DLM USEQ v23 | E6: Modeling_Output_Profile | F6: RMS 17.0 NA Stochastic Event Rates | L6: =_xlfn.CONCAT(Metadata!$B$1,"_Quarterly_USEQ") -> _Quarterly_USEQ
A7: =_xlfn.CONCAT("RMS_EDM_",Metadata!$B$1,"_Quarterly_USEQ") -> RMS_EDM__Quarterly_USEQ | B7: USEQ_CHFS | C7: USEQ_CHFS | D7: DLM USEQ v23 | E7: Modeling_Output_Profile | F7: RMS 17.0 NA Stochastic Event Rates | G7: XPR_1_95 | H7: XPR_1_100 | L7: =_xlfn.CONCAT(Metadata!$B$1,"_Quarterly_USEQ") -> _Quarterly_USEQ
A8: =_xlfn.CONCAT("RMS_EDM_",Metadata!$B$1,"_Quarterly_USEQ") -> RMS_EDM__Quarterly_USEQ | B8: USEQ_Condo | C8: USEQ_Condo | D8: DLM USEQ v23 | E8: Modeling_Output_Profile | F8: RMS 17.0 NA Stochastic Event Rates | G8: XPR_1_95 | H8: XPR_1_100 | L8: =_xlfn.CONCAT(Metadata!$B$1,"_Quarterly_USEQ") -> _Quarterly_USEQ
A9: =_xlfn.CONCAT("RMS_EDM_",Metadata!$B$1,"_Quarterly_USEQ") -> RMS_EDM__Quarterly_USEQ | B9: USEQ_Renters | C9: USEQ_Renters | D9: DLM USEQ v23 | E9: Modeling_Output_Profile | F9: RMS 17.0 NA Stochastic Event Rates | G9: XPR_1_95 | H9: XPR_1_100 | L9: =_xlfn.CONCAT(Metadata!$B$1,"_Quarterly_USEQ") -> _Quarterly_USEQ
A10: =_xlfn.CONCAT("RMS_EDM_",Metadata!$B$1,"_Quarterly_USEQ") -> RMS_EDM__Quarterly_USEQ | B10: USEQ_Manufactured | C10: USEQ_Manufactured | D10: DLM USEQ v23 | E10: Modeling_Output_Profile | F10: RMS 17.0 NA Stochastic Event Rates | G10: XPR_1_95 | H10: XPR_1_100 | L10: =_xlfn.CONCAT(Metadata!$B$1,"_Quarterly_USEQ") -> _Quarterly_USEQ
A11: =_xlfn.CONCAT("RMS_EDM_",Metadata!$B$1,"_Quarterly_USFF") -> RMS_EDM__Quarterly_USFF | B11: USFF_Geico_75HIP2 | C11: USFF_Geico_75HIP2 | D11: DLM USFF v23 | E11: Modeling_Output_Profile | F11: RMS 17.0 NA Stochastic Event Rates | G11: Geico_2.075QS | L11: =_xlfn.CONCAT(Metadata!$B$1,"_Quarterly_USFF") -> _Quarterly_USFF
A12: =_xlfn.CONCAT("RMS_EDM_",Metadata!$B$1,"_Quarterly_USFF") -> RMS_EDM__Quarterly_USFF | B12: USFF_Geico_HIP1 | C12: USFF_Geico_HIP1 | D12: DLM USFF v23 | E12: Modeling_Output_Profile | F12: RMS 17.0 NA Stochastic Event Rates | G12: XPR_1_95 | H12: XPR_1_100 | L12: =_xlfn.CONCAT(Metadata!$B$1,"_Quarterly_USFF") -> _Quarterly_USFF
A13: =_xlfn.CONCAT("RMS_EDM_",Metadata!$B$1,"_Quarterly_USFF") -> RMS_EDM__Quarterly_USFF | B13: USFF_Clay_Homes | C13: USFF_Clay_Homes | D13: DLM USFF v23 | E13: Modeling_Output_Profile | F13: RMS 17.0 NA Stochastic Event Rates | L13: =_xlfn.CONCAT(Metadata!$B$1,"_Quarterly_USFF") -> _Quarterly_USFF
A14: =_xlfn.CONCAT("RMS_EDM_",Metadata!$B$1,"_Quarterly_USFF") -> RMS_EDM__Quarterly_USFF | B14: USFF_Clay_21st | C14: USFF_Clay_21st | D14: DLM USFF v23 | E14: Modeling_Output_Profile | F14: RMS 17.0 NA Stochastic Event Rates | L14: =_xlfn.CONCAT(Metadata!$B$1,"_Quarterly_USFF") -> _Quarterly_USFF
A15: =_xlfn.CONCAT("RMS_EDM_",Metadata!$B$1,"_Quarterly_USFF") -> RMS_EDM__Quarterly_USFF | B15: USFF_Other | C15: USFF_Other | D15: DLM USFF v23 | E15: Modeling_Output_Profile | F15: RMS 17.0 NA Stochastic Event Rates | G15: XPR_1_95 | H15: XPR_1_100 | L15: =_xlfn.CONCAT(Metadata!$B$1,"_Quarterly_USFF") -> _Quarterly_USFF
A16: =_xlfn.CONCAT("RMS_EDM_",Metadata!$B$1,"_Quarterly_USFF") -> RMS_EDM__Quarterly_USFF | B16: USFF_CHFS | C16: USFF_CHFS | D16: DLM USFF v23 | E16: Modeling_Output_Profile | F16: RMS 17.0 NA Stochastic Event Rates | G16: XPR_1_95 | H16: XPR_1_100 | L16: =_xlfn.CONCAT(Metadata!$B$1,"_Quarterly_USFF") -> _Quarterly_USFF
A17: =_xlfn.CONCAT("RMS_EDM_",Metadata!$B$1,"_Quarterly_USFF") -> RMS_EDM__Quarterly_USFF | B17: USFF_Condo | C17: USFF_Condo | D17: DLM USFF v23 | E17: Modeling_Output_Profile | F17: RMS 17.0 NA Stochastic Event Rates | G17: XPR_1_95 | H17: XPR_1_100 | L17: =_xlfn.CONCAT(Metadata!$B$1,"_Quarterly_USFF") -> _Quarterly_USFF
A18: =_xlfn.CONCAT("RMS_EDM_",Metadata!$B$1,"_Quarterly_USFF") -> RMS_EDM__Quarterly_USFF | B18: USFF_Renters | C18: USFF_Renters | D18: DLM USFF v23 | E18: Modeling_Output_Profile | F18: RMS 17.0 NA Stochastic Event Rates | G18: XPR_1_95 | H18: XPR_1_100 | L18: =_xlfn.CONCAT(Metadata!$B$1,"_Quarterly_USFF") -> _Quarterly_USFF
A19: =_xlfn.CONCAT("RMS_EDM_",Metadata!$B$1,"_Quarterly_USFF") -> RMS_EDM__Quarterly_USFF | B19: USFF_Manufactured | C19: USFF_Manufactured | D19: DLM USFF v23 | E19: Modeling_Output_Profile | F19: RMS 17.0 NA Stochastic Event Rates | G19: XPR_1_95 | H19: XPR_1_100 | L19: =_xlfn.CONCAT(Metadata!$B$1,"_Quarterly_USFF") -> _Quarterly_USFF
A20: =_xlfn.CONCAT("RMS_EDM_",Metadata!$B$1,"_Quarterly_USFF") -> RMS_EDM__Quarterly_USFF | B20: USFF_Lender_P | C20: USFF_Lender_P | D20: DLM USFF v23 | E20: Modeling_Output_Profile | F20: RMS 17.0 NA Stochastic Event Rates | G20: XPR_1_95 | H20: XPR_1_100 | L20: =_xlfn.CONCAT(Metadata!$B$1,"_Quarterly_USFF") -> _Quarterly_USFF
A21: =_xlfn.CONCAT("RMS_EDM_",Metadata!$B$1,"_Quarterly_USFL") -> RMS_EDM__Quarterly_USFL | B21: USFL_Other_Other | C21: USFL_Other_Other_LT | D21: DLM USFL (85% SS) v23 | E21: Modeling_Output_Profile | F21: RMS 2023 Historical Event Rates | G21: XPR_1_95 | H21: XPR_1_100 | L21: =_xlfn.CONCAT(Metadata!$B$1,"_Quarterly_USFL_LT") -> _Quarterly_USFL_LT
A22: =_xlfn.CONCAT("RMS_EDM_",Metadata!$B$1,"_Quarterly_USFL") -> RMS_EDM__Quarterly_USFL | B22: USFL_Other_Renters | C22: USFL_Other_Renters_LT | D22: DLM USFL (85% SS) v23 | E22: Modeling_Output_Profile | F22: RMS 2023 Historical Event Rates | G22: XPR_1_95 | H22: XPR_1_100 | L22: =_xlfn.CONCAT(Metadata!$B$1,"_Quarterly_USFL_LT") -> _Quarterly_USFL_LT
A23: =_xlfn.CONCAT("RMS_EDM_",Metadata!$B$1,"_Quarterly_USFL") -> RMS_EDM__Quarterly_USFL | B23: USFL_Other_Maufactu | C23: USFL_Other_Maufactu_LT | D23: DLM USFL (85% SS) v23 | E23: Modeling_Output_Profile | F23: RMS 2023 Historical Event Rates | G23: XPR_1_95 | H23: XPR_1_100 | L23: =_xlfn.CONCAT(Metadata!$B$1,"_Quarterly_USFL_LT") -> _Quarterly_USFL_LT
A24: =_xlfn.CONCAT("RMS_EDM_",Metadata!$B$1,"_Quarterly_USFL") -> RMS_EDM__Quarterly_USFL | B24: USFL_Other_Lender_P | C24: USFL_Other_Lender_P_LT | D24: DLM USFL (85% SS) v23 | E24: Modeling_Output_Profile | F24: RMS 2023 Historical Event Rates | G24: XPR_1_95 | H24: XPR_1_100 | L24: =_xlfn.CONCAT(Metadata!$B$1,"_Quarterly_USFL_LT") -> _Quarterly_USFL_LT
A25: =_xlfn.CONCAT("RMS_EDM_",Metadata!$B$1,"_Quarterly_USFL") -> RMS_EDM__Quarterly_USFL | B25: USFL_Excess | C25: USFL_Excess_LT | D25: DLM USFL (65% SS) v23 | E25: Modeling_Output_Profile | F25: RMS 2023 Historical Event Rates | G25: XPR_1_95 | H25: XPR_1_100 | L25: =_xlfn.CONCAT(Metadata!$B$1,"_Quarterly_USFL_LT") -> _Quarterly_USFL_LT
A26: =_xlfn.CONCAT("RMS_EDM_",Metadata!$B$1,"_Quarterly_USFL") -> RMS_EDM__Quarterly_USFL | B26: USFL_Commercial | C26: USFL_Commercial_LT | D26: DLM USFL (65% SS) v23 | E26: Modeling_Output_Profile | F26: RMS 2023 Historical Event Rates | G26: XPR_1_95 | H26: XPR_1_100 | L26: =_xlfn.CONCAT(Metadata!$B$1,"_Quarterly_USFL_LT") -> _Quarterly_USFL_LT
A27: =_xlfn.CONCAT("RMS_EDM_",Metadata!$B$1,"_Quarterly_USHU") -> RMS_EDM__Quarterly_USHU | B27: USHU_Leak_Geico_75H2 | C27: USHU_Leak_Geico_75H2_LT | D27: DLM USHU_Leak (9% SS) v23 | E27: Modeling_Output_Profile | F27: RMS 2023 Historical Event Rates | G27: Geico_2.075QS | L27: =_xlfn.CONCAT(Metadata!$B$1,"_Quarterly_USHU_LT") -> _Quarterly_USHU_LT
A28: =_xlfn.CONCAT("RMS_EDM_",Metadata!$B$1,"_Quarterly_USHU") -> RMS_EDM__Quarterly_USHU | B28: USHU_Leak_Geico_HIP1 | C28: USHU_Leak_Geico_HIP1_LT | D28: DLM USHU_Leak (9% SS) v23 | E28: Modeling_Output_Profile | F28: RMS 2023 Historical Event Rates | G28: XPR_1_95 | H28: XPR_1_100 | L28: =_xlfn.CONCAT(Metadata!$B$1,"_Quarterly_USHU_LT") -> _Quarterly_USHU_LT
A29: =_xlfn.CONCAT("RMS_EDM_",Metadata!$B$1,"_Quarterly_USHU") -> RMS_EDM__Quarterly_USHU | B29: USHU_Full_Clay_Homes | C29: USHU_Full_Clay_Homes_LT | D29: DLM USHU_Full (85% SS) v23 | E29: Modeling_Output_Profile | F29: RMS 2023 Historical Event Rates | L29: =_xlfn.CONCAT(Metadata!$B$1,"_Quarterly_USHU_LT") -> _Quarterly_USHU_LT
A30: =_xlfn.CONCAT("RMS_EDM_",Metadata!$B$1,"_Quarterly_USHU") -> RMS_EDM__Quarterly_USHU | B30: USHU_Full_Clay_21st | C30: USHU_Full_Clay_21st_LT | D30: DLM USHU_Full (85% SS) v23 | E30: Modeling_Output_Profile | F30: RMS 2023 Historical Event Rates | L30: =_xlfn.CONCAT(Metadata!$B$1,"_Quarterly_USHU_LT") -> _Quarterly_USHU_LT
A31: =_xlfn.CONCAT("RMS_EDM_",Metadata!$B$1,"_Quarterly_USHU") -> RMS_EDM__Quarterly_USHU | B31: USHU_Full_Other | C31: USHU_Full_Other_LT | D31: DLM USHU_Full (85% SS) v23 | E31: Modeling_Output_Profile | F31: RMS 2023 Historical Event Rates | G31: XPR_1_95 | H31: XPR_1_100 | L31: =_xlfn.CONCAT(Metadata!$B$1,"_Quarterly_USHU_LT") -> _Quarterly_USHU_LT
A32: =_xlfn.CONCAT("RMS_EDM_",Metadata!$B$1,"_Quarterly_USHU") -> RMS_EDM__Quarterly_USHU | B32: USHU_Full_Renters | C32: USHU_Full_Renters_LT | D32: DLM USHU_Full (85% SS) v23 | E32: Modeling_Output_Profile | F32: RMS 2023 Historical Event Rates | G32: XPR_1_95 | H32: XPR_1_100 | L32: =_xlfn.CONCAT(Metadata!$B$1,"_Quarterly_USHU_LT") -> _Quarterly_USHU_LT
A33: =_xlfn.CONCAT("RMS_EDM_",Metadata!$B$1,"_Quarterly_USHU") -> RMS_EDM__Quarterly_USHU | B33: USHU_Full_Manufact | C33: USHU_Full_Manufact_LT | D33: DLM USHU_Full (85% SS) v23 | E33: Modeling_Output_Profile | F33: RMS 2023 Historical Event Rates | G33: XPR_1_95 | H33: XPR_1_100 | L33: =_xlfn.CONCAT(Metadata!$B$1,"_Quarterly_USHU_LT") -> _Quarterly_USHU_LT
A34: =_xlfn.CONCAT("RMS_EDM_",Metadata!$B$1,"_Quarterly_USHU") -> RMS_EDM__Quarterly_USHU | B34: USHU_Full_Lender_P | C34: USHU_Full_Lender_P_LT | D34: DLM USHU_Full (85% SS) v23 | E34: Modeling_Output_Profile | F34: RMS 2023 Historical Event Rates | G34: XPR_1_95 | H34: XPR_1_100 | L34: =_xlfn.CONCAT(Metadata!$B$1,"_Quarterly_USHU_LT") -> _Quarterly_USHU_LT
A35: =_xlfn.CONCAT("RMS_EDM_",Metadata!$B$1,"_Quarterly_USHU") -> RMS_EDM__Quarterly_USHU | B35: USHU_Leak_Clay_Homes | C35: USHU_Leak_Clay_Homes_LT | D35: DLM USHU_Leak (9% SS) v23 | E35: Modeling_Output_Profile | F35: RMS 2023 Historical Event Rates | L35: =_xlfn.CONCAT(Metadata!$B$1,"_Quarterly_USHU_LT") -> _Quarterly_USHU_LT
A36: =_xlfn.CONCAT("RMS_EDM_",Metadata!$B$1,"_Quarterly_USHU") -> RMS_EDM__Quarterly_USHU | B36: USHU_Leak_Clay_21st | C36: USHU_Leak_Clay_21st_LT | D36: DLM USHU_Leak (9% SS) v23 | E36: Modeling_Output_Profile | F36: RMS 2023 Historical Event Rates | L36: =_xlfn.CONCAT(Metadata!$B$1,"_Quarterly_USHU_LT") -> _Quarterly_USHU_LT
A37: =_xlfn.CONCAT("RMS_EDM_",Metadata!$B$1,"_Quarterly_USHU") -> RMS_EDM__Quarterly_USHU | B37: USHU_Leak_Other | C37: USHU_Leak_Other_LT | D37: DLM USHU_Leak (9% SS) v23 | E37: Modeling_Output_Profile | F37: RMS 2023 Historical Event Rates | G37: XPR_1_95 | H37: XPR_1_100 | L37: =_xlfn.CONCAT(Metadata!$B$1,"_Quarterly_USHU_LT") -> _Quarterly_USHU_LT
A38: =_xlfn.CONCAT("RMS_EDM_",Metadata!$B$1,"_Quarterly_USHU") -> RMS_EDM__Quarterly_USHU | B38: USHU_Leak_CHFS | C38: USHU_Leak_CHFS_LT | D38: DLM USHU_Leak (9% SS) v23 | E38: Modeling_Output_Profile | F38: RMS 2023 Historical Event Rates | G38: XPR_1_95 | H38: XPR_1_100 | L38: =_xlfn.CONCAT(Metadata!$B$1,"_Quarterly_USHU_LT") -> _Quarterly_USHU_LT
A39: =_xlfn.CONCAT("RMS_EDM_",Metadata!$B$1,"_Quarterly_USHU") -> RMS_EDM__Quarterly_USHU | B39: USHU_Leak_Condo | C39: USHU_Leak_Condo_LT | D39: DLM USHU_Leak (9% SS) v23 | E39: Modeling_Output_Profile | F39: RMS 2023 Historical Event Rates | G39: XPR_1_95 | H39: XPR_1_100 | L39: =_xlfn.CONCAT(Metadata!$B$1,"_Quarterly_USHU_LT") -> _Quarterly_USHU_LT
A40: =_xlfn.CONCAT("RMS_EDM_",Metadata!$B$1,"_Quarterly_USHU") -> RMS_EDM__Quarterly_USHU | B40: USHU_Leak_Renters | C40: USHU_Leak_Renters_LT | D40: DLM USHU_Leak (9% SS) v23 | E40: Modeling_Output_Profile | F40: RMS 2023 Historical Event Rates | G40: XPR_1_95 | H40: XPR_1_100 | L40: =_xlfn.CONCAT(Metadata!$B$1,"_Quarterly_USHU_LT") -> _Quarterly_USHU_LT
...

Sheet Groupings
A1: Group_Name | B1: Item1 | C1: Item2 | D1: Item3 | E1: Item4 | F1: Item5 | G1: Item6 | H1: Item7 | I1: Item8 | J1: Item9 | K1: Item10 | L1: Item11 | M1: Item12 | N1: Item13 | O1: Item14 | P1: Item15 | Q1: Item16 | R1: Item17 | S1: Item18 | T1: Item19 | U1: Item20 | V1: Item21 | W1: Item22 | X1: Item23 | Y1: Item24 | Z1: Item25 | AA1: Item26 | AB1: Item27 | AC1: Item28 | AD1: Item29 | AE1: Item30 | AF1: Item31 | AG1: Item32 | AH1: Item33 | AI1: Item34 | AJ1: Item35 | AK1: Item36 | AL1: Item37 | AM1: Item38 | AN1: Item39 | AO1: Item40 | AP1: Item41 | AQ1: Item42 | AR1: Item43 | AS1: Item44 | AT1: Item45 | AU1: Item46 | AV1: Item47 | AW1: Item48 | AX1: Item49 | AY1: Item50
A2: =_xlfn.CONCAT(Metadata!$B$1,"_USST_Geico_HIP2_Group") -> _USST_Geico_HIP2_Group | B2: USST_Geico_75HIP2_High_Frq | C2: USST_Geico_75HIP2_Low_Frq
A3: =_xlfn.CONCAT(Metadata!$B$1,"_USHU_LT_Manufactured_Housing_Group") -> _USHU_LT_Manufactured_Housing_Group | B3: USHU_Full_Manufact_LT | C3: USHU_Leak_Manufact_LT
A4: =_xlfn.CONCAT(Metadata!$B$1,"_USHU_NT_Manufactured_Housing_Group") -> _USHU_NT_Manufactured_Housing_Group | B4: USHU_Full_Manufact_NT | C4: USHU_Leak_Manufact_NT
A5: =_xlfn.CONCAT(Metadata!$B$1,"_USHU_LT_Renters_Group") -> _USHU_LT_Renters_Group | B5: USHU_Full_Renters_LT | C5: USHU_Leak_Renters_LT
A6: =_xlfn.CONCAT(Metadata!$B$1,"_USHU_NT_Renters_Group") -> _USHU_NT_Renters_Group | B6: USHU_Full_Renters_NT | C6: USHU_Leak_Renters_NT
A7: =_xlfn.CONCAT(Metadata!$B$1,"_USHU_LT_Other_Group") -> _USHU_LT_Other_Group | B7: USHU_Full_Other_LT | C7: USHU_Leak_Other_LT
A8: =_xlfn.CONCAT(Metadata!$B$1,"_USHU_NT_Other_Group") -> _USHU_NT_Other_Group | B8: USHU_Full_Other_NT | C8: USHU_Leak_Other_NT
A9: =_xlfn.CONCAT(Metadata!$B$1,"_USHU_LT_LendarPlaced_Group") -> _USHU_LT_LendarPlaced_Group | B9: USHU_Full_Lender_P_LT | C9: USHU_Leak_Lender_P_LT
A10: =_xlfn.CONCAT(Metadata!$B$1,"_USHU_NT_LendarPlaced_Group") -> _USHU_NT_LendarPlaced_Group | B10: USHU_Full_Lender_P_NT | C10: USHU_Leak_Lender_P_NT
A11: =_xlfn.CONCAT(Metadata!$B$1,"_NT_USHU_Group") -> _NT_USHU_Group | B11: USHU_Leak_Geico_75H2_NT | C11: USHU_Leak_Geico_HIP1_NT | D11: USHU_Full_Other_NT | E11: USHU_Full_Renters_NT | F11: USHU_Full_Manufact_NT | G11: USHU_Full_Lender_P_NT | H11: USHU_Leak_Other_NT | I11: USHU_Leak_CHFS_NT | J11: USHU_Leak_Condo_NT | K11: USHU_Leak_Renters_NT | L11: USHU_Leak_Manufact_NT | M11: USHU_Leak_Lender_P_NT
A12: =_xlfn.CONCAT(Metadata!$B$1,"_LT_USHU_Group") -> _LT_USHU_Group | B12: USHU_Leak_Geico_75H2_LT | C12: USHU_Leak_Geico_HIP1_LT | D12: USHU_Full_Other_LT | E12: USHU_Full_Renters_LT | F12: USHU_Full_Manufact_LT | G12: USHU_Full_Lender_P_LT | H12: USHU_Leak_Other_LT | I12: USHU_Leak_CHFS_LT | J12: USHU_Leak_Condo_LT | K12: USHU_Leak_Renters_LT | L12: USHU_Leak_Manufact_LT | M12: USHU_Leak_Lender_P_LT
A13: =_xlfn.CONCAT(Metadata!$B$1,"_USEQ_Group") -> _USEQ_Group | B13: USEQ_CHFS | C13: USEQ_Condo | D13: USEQ_Renters | E13: USEQ_Manufactured
A14: =_xlfn.CONCAT(Metadata!$B$1,"_USFF_Group") -> _USFF_Group | B14: USFF_Geico_75HIP2 | C14: USFF_Geico_HIP1 | D14: USFF_Other | E14: USFF_CHFS | F14: USFF_Condo | G14: USFF_Renters | H14: USFF_Manufactured | I14: USFF_Lender_P
A15: =_xlfn.CONCAT(Metadata!$B$1,"_USWF_Group") -> _USWF_Group | B15: USWF_Other | C15: USWF_CHFS | D15: USWF_Condo | E15: USWF_Renters | F15: USWF_Manufactured | G15: USWF_Geico_75HIP2 | H15: USWF_Geico_HIP1 | I15: USWF_Lender_P
A16: =_xlfn.CONCAT(Metadata!$B$1,"_USST_Group") -> _USST_Group | B16: USST_Other_High_Frq | C16: USST_CHFS_High_Frq | D16: USST_Condo_High_Frq | E16: USST_Renters_High_Frq | F16: USST_Manufactured_High_Frq | G16: USST_Geico_75HIP2_High_Frq | H16: USST_Geico_HIP1_High_Frq | I16: USST_Lender_P_High_Frq | J16: USST_Other_Low_Frq | K16: USST_CHFS_Low_Frq | L16: USST_Condo_Low_Frq | M16: USST_Renters_Low_Frq | N16: USST_Manufactured_Low_Frq | O16: USST_Geico_75HIP2_Low_Frq | P16: USST_Geico_HIP1_Low_Frq | Q16: USST_Lender_P_Low_Frq
A17: =_xlfn.CONCAT(Metadata!$B$1,"_LenderPlaced_LT_All_PerilxWFIF_Group") -> _LenderPlaced_LT_All_PerilxWFIF_Group | B17: CBHU_LT | C17: USFF_Lender_P | D17: USFL_Other_Lender_P_LT | E17: USHU_Full_Lender_P_LT | F17: USHU_Leak_Lender_P_LT | G17: USST_Lender_P_High_Frq | H17: USST_Lender_P_Low_Frq | I17: CBEQ
A18: =_xlfn.CONCAT(Metadata!$B$1,"_LenderPlaced_LT_All_Peril_Group") -> _LenderPlaced_LT_All_Peril_Group | B18: CBHU_LT | C18: USFF_Lender_P | D18: USFL_Other_Lender_P_LT | E18: USHU_Full_Lender_P_LT | F18: USHU_Leak_Lender_P_LT | G18: USST_Lender_P_High_Frq | H18: USST_Lender_P_Low_Frq | I18: USWF_Lender_P | J18: CBEQ
A19: =_xlfn.CONCAT(Metadata!$B$1,"_LenderPlacedxCB_LT_All_PerilxWFIF_Group") -> _LenderPlacedxCB_LT_All_PerilxWFIF_Group | B19: USFF_Lender_P | C19: USFL_Other_Lender_P_LT | D19: USHU_Full_Lender_P_LT | E19: USHU_Leak_Lender_P_LT | F19: USST_Lender_P_High_Frq | G19: USST_Lender_P_Low_Frq
A20: =_xlfn.CONCAT(Metadata!$B$1,"_LenderPlacedxCB_LT_All_Peril_Group") -> _LenderPlacedxCB_LT_All_Peril_Group | B20: USFF_Lender_P | C20: USFL_Other_Lender_P_LT | D20: USHU_Full_Lender_P_LT | E20: USHU_Leak_Lender_P_LT | F20: USST_Lender_P_High_Frq | G20: USST_Lender_P_Low_Frq | H20: USWF_Lender_P
A21: =_xlfn.CONCAT(Metadata!$B$1,"_Geico_HIP2_LT_All_Peril_Group") -> _Geico_HIP2_LT_All_Peril_Group | B21: USFF_Geico_75HIP2 | C21: USHU_Leak_Geico_75H2_LT | D21: USST_Geico_75HIP2_High_Frq | E21: USST_Geico_75HIP2_Low_Frq | F21: USWF_Geico_75HIP2
A22: =_xlfn.CONCAT(Metadata!$B$1,"_Geico_HIP2_LT_All_PerilxWFIF_Group") -> _Geico_HIP2_LT_All_PerilxWFIF_Group | B22: USFF_Geico_75HIP2 | C22: USHU_Leak_Geico_75H2_LT | D22: USST_Geico_75HIP2_High_Frq | E22: USST_Geico_75HIP2_Low_Frq
A23: =_xlfn.CONCAT(Metadata!$B$1,"_Condominium_LT_All_Peril_Group") -> _Condominium_LT_All_Peril_Group | B23: USEQ_Condo | C23: USFF_Condo | D23: USHU_Leak_Condo_LT | E23: USST_Condo_High_Frq | F23: USST_Condo_Low_Frq | G23: USWF_Condo
A24: =_xlfn.CONCAT(Metadata!$B$1,"_Condominium_LT_All_PerilxWFIF_Group") -> _Condominium_LT_All_PerilxWFIF_Group | B24: USEQ_Condo | C24: USFF_Condo | D24: USHU_Leak_Condo_LT | E24: USST_Condo_High_Frq | F24: USST_Condo_Low_Frq
A25: =_xlfn.CONCAT(Metadata!$B$1,"_Geico_HIP1_LT_All_Peril_Group") -> _Geico_HIP1_LT_All_Peril_Group | B25: USFF_Geico_HIP1 | C25: USHU_Leak_Geico_HIP1_LT | D25: USST_Geico_HIP1_High_Frq | E25: USST_Geico_HIP1_Low_Frq | F25: USWF_Geico_HIP1
A26: =_xlfn.CONCAT(Metadata!$B$1,"_Geico_HIP1_LT_All_PerilxWFIF_Group") -> _Geico_HIP1_LT_All_PerilxWFIF_Group | B26: USFF_Geico_HIP1 | C26: USHU_Leak_Geico_HIP1_LT | D26: USST_Geico_HIP1_High_Frq | E26: USST_Geico_HIP1_Low_Frq
A27: =_xlfn.CONCAT(Metadata!$B$1,"_Renters_LT_All_Peril_Group") -> _Renters_LT_All_Peril_Group | B27: USEQ_Renters | C27: USFF_Renters | D27: USFL_Other_Renters_LT | E27: USHU_Full_Renters_LT | F27: USHU_Leak_Renters_LT | G27: USST_Renters_High_Frq | H27: USST_Renters_Low_Frq | I27: USWF_Renters
A28: =_xlfn.CONCAT(Metadata!$B$1,"_Renters_LT_All_PerilxWFIF_Group") -> _Renters_LT_All_PerilxWFIF_Group | B28: USEQ_Renters | C28: USFF_Renters | D28: USFL_Other_Renters_LT | E28: USHU_Full_Renters_LT | F28: USHU_Leak_Renters_LT | G28: USST_Renters_High_Frq | H28: USST_Renters_Low_Frq
A29: =_xlfn.CONCAT(Metadata!$B$1,"_Choice_First_Select_LT_All_Peril_Group") -> _Choice_First_Select_LT_All_Peril_Group | B29: USEQ_CHFS | C29: USFF_CHFS | D29: USHU_Leak_CHFS_LT | E29: USST_CHFS_High_Frq | F29: USST_CHFS_Low_Frq | G29: USWF_CHFS
A30: =_xlfn.CONCAT(Metadata!$B$1,"_Choice_First_Select_LT_All_PerilxWFIF_Group") -> _Choice_First_Select_LT_All_PerilxWFIF_Group | B30: USEQ_CHFS | C30: USFF_CHFS | D30: USHU_Leak_CHFS_LT | E30: USST_CHFS_High_Frq | F30: USST_CHFS_Low_Frq
A31: =_xlfn.CONCAT(Metadata!$B$1,"_Manufactured_Housing_LT_All_Peril_Group") -> _Manufactured_Housing_LT_All_Peril_Group | B31: USEQ_Manufactured | C31: USFF_Manufactured | D31: USFL_Other_Maufactu_LT | E31: USHU_Full_Manufact_LT | F31: USHU_Leak_Manufact_LT | G31: USST_Manufactured_High_Frq | H31: USST_Manufactured_Low_Frq | I31: USWF_Manufactured
A32: =_xlfn.CONCAT(Metadata!$B$1,"_Manufactured_Housing_LT_All_PerilxWFIF_Group") -> _Manufactured_Housing_LT_All_PerilxWFIF_Group | B32: USEQ_Manufactured | C32: USFF_Manufactured | D32: USFL_Other_Maufactu_LT | E32: USHU_Full_Manufact_LT | F32: USHU_Leak_Manufact_LT | G32: USST_Manufactured_High_Frq | H32: USST_Manufactured_Low_Frq
A33: =_xlfn.CONCAT(Metadata!$B$1,"_Other_LT_All_Peril_Group") -> _Other_LT_All_Peril_Group | B33: USFF_Other | C33: USFL_Other_Other_LT | D33: USHU_Full_Other_LT | E33: USHU_Leak_Other_LT | F33: USST_Other_High_Frq | G33: USST_Other_Low_Frq | H33: USWF_Other
A34: =_xlfn.CONCAT(Metadata!$B$1,"_Other_LT_All_PerilxWFIF_Group") -> _Other_LT_All_PerilxWFIF_Group | B34: USFF_Other | C34: USFL_Other_Other_LT | D34: USHU_Full_Other_LT | E34: USHU_Leak_Other_LT | F34: USST_Other_High_Frq | G34: USST_Other_Low_Frq
A35: =_xlfn.CONCAT(Metadata!$B$1,"_LenderPlaced_NT_All_PerilxWFIF_Group") -> _LenderPlaced_NT_All_PerilxWFIF_Group | B35: CBHU_NT | C35: USFF_Lender_P | D35: USFL_Other_Lender_P_NT | E35: USST_Lender_P_High_Frq | F35: USHU_Full_Lender_P_NT | G35: USHU_Leak_Lender_P_NT | H35: USST_Lender_P_Low_Frq | I35: CBEQ
A36: =_xlfn.CONCAT(Metadata!$B$1,"_LenderPlaced_NT_All_Peril_Group") -> _LenderPlaced_NT_All_Peril_Group | B36: CBHU_NT | C36: USFF_Lender_P | D36: USFL_Other_Lender_P_NT | E36: USST_Lender_P_High_Frq | F36: USHU_Full_Lender_P_NT | G36: USHU_Leak_Lender_P_NT | H36: USST_Lender_P_Low_Frq | I36: USWF_Lender_P | J36: CBEQ
A37: =_xlfn.CONCAT(Metadata!$B$1,"_LenderPlacedxCB_NT_All_PerilxWFIF_Group") -> _LenderPlacedxCB_NT_All_PerilxWFIF_Group | B37: USFF_Lender_P | C37: USFL_Other_Lender_P_NT | D37: USST_Lender_P_High_Frq | E37: USHU_Full_Lender_P_NT | F37: USHU_Leak_Lender_P_NT | G37: USST_Lender_P_Low_Frq
A38: =_xlfn.CONCAT(Metadata!$B$1,"_LenderPlacedxCB_NT_All_Peril_Group") -> _LenderPlacedxCB_NT_All_Peril_Group | B38: USFF_Lender_P | C38: USFL_Other_Lender_P_NT | D38: USST_Lender_P_High_Frq | E38: USHU_Full_Lender_P_NT | F38: USHU_Leak_Lender_P_NT | G38: USST_Lender_P_Low_Frq | H38: USWF_Lender_P
A39: =_xlfn.CONCAT(Metadata!$B$1,"_Geico_HIP2_NT_All_Peril_Group") -> _Geico_HIP2_NT_All_Peril_Group | B39: USFF_Geico_75HIP2 | C39: USST_Geico_75HIP2_High_Frq | D39: USHU_Leak_Geico_75H2_NT | E39: USST_Geico_75HIP2_Low_Frq | F39: USWF_Geico_75HIP2
A40: =_xlfn.CONCAT(Metadata!$B$1,"_Geico_HIP2_NT_All_PerilxWFIF_Group") -> _Geico_HIP2_NT_All_PerilxWFIF_Group | B40: USFF_Geico_75HIP2 | C40: USST_Geico_75HIP2_High_Frq | D40: USHU_Leak_Geico_75H2_NT | E40: USST_Geico_75HIP2_Low_Frq
...

Sheet Products and Perils
A1: Analysis Name | B1: Peril | C1: Product Group
A2: CBHU_LT | B2: Standard CBHU | C2: Lender Placed
A3: CBHU_LT | B3: Standard CBHU | C3: All_xClay
A4: CBHU_NT | B4: WSST CBHU | C4: Lender Placed
A5: CBHU_NT | B5: WSST CBHU | C5: All_xClay
A6: CBEQ | B6: CBEQ | C6: Lender Placed
A7: CBEQ | B7: CBEQ | C7: All_xClay
A8: USEQ_Clay_Homes | B8: USEQ | C8: Clayton Homes
A9: USEQ_Clay_21st | B9: USEQ | C9: Clayton 21st Mort
A10: USEQ_CHFS | B10: USEQ | C10: Choice & First Select
A11: USEQ_Condo | B11: USEQ | C11: Condominium
A12: USEQ_Renters | B12: USEQ | C12: Renters
... A39: USHU_Leak_Geico_HIP1_LT | B39: Standard USHU | C39: Geico HIP 1.0
A40: USHU_Full_Clay_Homes_LT
A41: USHU_Full_Clay_21st_LT
A42: USHU_Full_Other_LT
A43: USHU_Full_Renters_LT
A44: USHU_Full_Manufact_LT
A45: USHU_Full_Lender_P_LT
A46: USHU_Leak_Clay_Homes_LT
A47: USHU_Leak_Clay_21st_LT
A48: USHU_Leak_Other_LT
A49: USHU_Leak_CHFS_LT | B49: Standard USHU | C49: Choice & First Select
A50: USHU_Leak_Condo_LT | B50: Standard USHU | C50: Condominium
A51: USHU_Leak_Renters_LT
A52: USHU_Leak_Manufact_LT
A53: USHU_Leak_Lender_P_LT
A54: USST_Clay_Homes_High_Frq
A55: USST_Clay_21st_High_Frq
A56: USST_Other_High_Frq
A57: USST_CHFS_High_Frq
A58: USST_Condo_High_Frq
A59: USST_Renters_High_Frq
A60: USST_Manufactured_High_Frq
A61: USST_Geico_75HIP2_High_Frq
A62: USST_Geico_HIP1_High_Frq
A63: USST_Lender_P_High_Frq
A64: USWF_Clay_Homes | B64: USWF | C64: Clayton Homes
A65: USWF_Clay_21st | B65: USWF | C65: Clayton 21st Mort
A66: USWF_Other | B66: USWF | C66: Other
...

Sheet Moody's Reference Data
A1: Model Profiles | B1: Output Profiles | C1: Event Rate Schemes
A2: CBHU RL22 | B2: By_State_Modeling_Output_Profile | C2: 2011 Historical Event Rates
A3: CBHU_NT | B3: CBHU_Test_OP | C3: 2013 Historical Event Rates
A4: Copy Of MICHAEL_MODEL_MISS_DLM | B4: CChia_Output_Profile | C4: 2015 Historical Event Rates
A5: DLM CBEQ | B5: Default | C5: 2017 MTR Alt - Active Baseline
A6: DLM CBEQ v23 | B6: HAZARD_Analysis | C6: 2017 MTR Alt - Forecast SST
A7: DLM CBHU | B7: HAZARD_Analysis_Sai | C7: 2017 MTR Alt - Inactive Phase
A8: DLM CBHU v23 | B8: HAZARD_Analysis_Sai_Policy | C8: 2017 MTR Alt - Lower Bound
A9: DLM USEQ | B9: JP_Test | C9: 2017 MTR Alt - Upper Bound
A10: DLM USEQ v23 | B10: Modeling_Output_Profile | C10: 2019 MTR Alt - Active Baseline
A11: DLM USFF | B11: Portfolio_Location | C11: 2019 MTR Alt - Forecast SST
A12: DLM USFF v23 | B12: Portfolio_State_Coverage_LocationAAL_GU_GR_RL | C12: 2019 MTR Alt - Inactive Phase
... A21: DLM USHU_Full (85% SS) | B21: RMS Scenario | C21: 2023 MTR Alt - Forecast SST
A22: DLM USHU_Full (85% SS) v23 | C22: 2023 MTR Alt - Inactive Baseline
A23: DLM USHU_Full (85% SS) v25 | C23: 2023 MTR Alt - Lower Bound
A24: DLM USHU_Leak (9% SS) | C24: 2023 MTR Alt - Upper Bound
A25: DLM USHU_Leak (9% SS) v23 | C25: 2025 MTR Alt - Active Baseline
A26: DLM USHU_Leak (9% SS) v25 | C26: 2025 MTR Alt - Forecast SST
A27: DLM USST High Frq | C27: 2025 MTR Alt - Inactive Baseline
A28: DLM USST High Frq v23 | C28: 2025 MTR Alt - Lower Bound
A29: DLM USST High and Low Frq v23 Tornado | C29: 2025 MTR Alt - Upper Bound
A30: DLM USST Low Frq | C30: HailCalc Stochastic Event Rates
A31: DLM USST Low Frq v23 | C31: RMS 11.0 Stochastic Event Rates
A32: Demo NA HU WF HD Model | C32: RMS 11.4 JP Stochastic Event Rates
A33: Flood_SS65 | C33: RMS 11.4 JP Long Term (Time-Independent) Rates
... A53: USST High and Low Frq v23 Wind | C53: RMS 2017 Stochastic Event Rates
C54: RMS 2019 Historical Event Rates
C55: RMS 2019 Stochastic Event Rates
C56: RMS 2021 Historical Event Rates
C57: RMS 2021 Stochastic Event Rates
C58: RMS 2023 Historical Event Rates
C59: RMS 2023 Stochastic Event Rates
C60: RMS 2025 Historical Event Rates
C61: RMS 2025 Stochastic Event Rates
C62: RMS 22.0 Stochastic Event Rates
C63: RMS 22.0 Long Term (Time-Independent) Rates
C64: RMS 22.0 Stochastic Event Rates
C65: RMS 24.0 Long Term (Time-Independent) Rates
... C76: RMS Stochastic Event Set
